<?xml version="1.0"?>
<robot xmlns:xacro="http://www.ros.org/wiki/xacro">
  <xacro:macro name="za_macro" params="prefix">

    <!-- link list -->
    <link name="${prefix}base_link">
      <visual>
        <geometry>
          <mesh filename="package://za_description/meshes/visual/base_link.dae"/>
        </geometry>
      </visual>
      <collision>
        <geometry>
          <mesh filename="package://za_description/meshes/collision/base_link_collision.stl"/>
        </geometry>
      </collision>
    </link>
    <link name="${prefix}link_1">
      <visual>
        <geometry>
          <mesh filename="package://za_description/meshes/visual/link_1.dae"/>
        </geometry>
      </visual>
      <collision>
        <geometry>
          <mesh filename="package://za_description/meshes/collision/link_1_collision.stl"/>
        </geometry>
      </collision>
    </link>
    <link name="${prefix}link_2">
      <visual>
        <geometry>
          <mesh filename="package://za_description/meshes/visual/link_2.dae"/>
        </geometry>
      </visual>
      <collision>
        <geometry>
          <mesh filename="package://za_description/meshes/collision/link_2_collision.stl"/>
        </geometry>
      </collision>
    </link>
    <link name="${prefix}link_3">
      <visual>
        <geometry>
          <mesh filename="package://za_description/meshes/visual/link_3.dae"/>
        </geometry>
      </visual>
      <collision>
        <geometry>
          <mesh filename="package://za_description/meshes/collision/link_3_collision.stl"/>
        </geometry>
      </collision>
    </link>
    <link name="${prefix}link_4">
      <visual>
        <geometry>
          <mesh filename="package://za_description/meshes/visual/link_4.dae"/>
        </geometry>
      </visual>
      <collision>
        <geometry>
          <mesh filename="package://za_description/meshes/collision/link_4_collision.stl"/>
        </geometry>
      </collision>
    </link>
    <link name="${prefix}link_5">
      <visual>
        <geometry>
          <mesh filename="package://za_description/meshes/visual/link_5.dae"/>
        </geometry>
      </visual>
      <collision>
        <geometry>
          <mesh filename="package://za_description/meshes/collision/link_5_collision.stl"/>
        </geometry>
      </collision>
    </link>
    <link name="${prefix}link_6">
      <visual>
        <geometry>
          <mesh filename="package://za_description/meshes/visual/link_6.dae"/>
        </geometry>
      </visual>
      <collision>
        <geometry>
          <mesh filename="package://za_description/meshes/collision/link_6_collision.stl"/>
        </geometry>
      </collision>
    </link>

    <!-- joint list -->
    <joint name="${prefix}joint_1" type="revolute">
      <parent link="${prefix}base_link"/>
      <child link="${prefix}link_1"/>
      <origin rpy="0.0 0.0 0.0" xyz="0 0 0.45"/>
      <axis xyz="0 0 1"/>
      <limit effort="0" lower="${radians(-170)}" upper="${radians(170)}" velocity="${radians(150)}"/>
    </joint>
    <joint name="${prefix}joint_2" type="revolute">
      <parent link="${prefix}link_1"/>
      <child link="${prefix}link_2"/>
      <origin rpy="0.0 0.0 0.0" xyz="0.025 0 0.0"/>
      <axis xyz="0 1 0"/>
      <limit effort="0" lower="${radians(-100)}" upper="${radians(130)}" velocity="${radians(112.5)}"/>
    </joint>
    <joint name="${prefix}joint_3" type="revolute">
      <parent link="${prefix}link_2"/>
      <child link="${prefix}link_3"/>
      <origin rpy="0.0 0.0 0.0" xyz="0.0 -0.001 0.454"/>
      <axis xyz="0 1 0"/>
      <limit effort="0" lower="${radians(-120)}" upper="${radians(65)}" velocity="${radians(150)}"/>
    </joint>
    <joint name="${prefix}joint_4" type="revolute">
      <parent link="${prefix}link_3"/>
      <child link="${prefix}link_4"/>
      <origin rpy="0.0 0.0 0.0" xyz="0.0 0.0 0.035"/>
      <axis xyz="1 0 0"/>
      <limit effort="0" lower="${radians(-180)}" upper="${radians(180)}" velocity="${radians(204.5)}"/>
    </joint>
    <joint name="${prefix}joint_5" type="revolute">
      <parent link="${prefix}link_4"/>
      <child link="${prefix}link_5"/>
      <origin rpy="0.0 0.0 0.0" xyz="0.4195 0.001 0.0"/>
      <axis xyz="0 1 0"/>
      <limit effort="0" lower="${radians(-140)}" upper="${radians(140)}" velocity="${radians(225)}"/>
    </joint>
    <joint name="${prefix}joint_6" type="revolute">
      <parent link="${prefix}link_5"/>
      <child link="${prefix}link_6"/>
      <origin rpy="0.0 0.0 0.0" xyz="0.1175 0.0 0.0"/>
      <axis xyz="1 0 0"/>
      <limit effort="0" lower="${radians(-360)}" upper="${radians(360)}" velocity="${radians(360)}"/>
    </joint>

    <!-- ROS-Industrial 'base' frame: base_link to Tormach World Coordinates transform -->
    <link name="${prefix}base" />
    <joint name="${prefix}base_link-base" type="fixed">
      <origin xyz="0 0 0" rpy="0 0 0"/>
      <parent link="${prefix}base_link"/>
      <child link="${prefix}base"/>
    </joint>

    <!-- ROS-Industrial 'flange' frame: attachment point for EEF models -->
    <link name="${prefix}flange" />
    <joint name="${prefix}joint_6-flange" type="fixed">
      <origin xyz="0 0 0" rpy="0 0 0"/>
      <parent link="${prefix}link_6"/>
      <child link="${prefix}flange"/>
    </joint>

    <!-- ROS-Industrial 'tool0' frame: all-zeros tool frame -->
    <link name="${prefix}tool0" />
    <joint name="${prefix}link_6-tool0" type="fixed">
      <origin xyz="0 0 0" rpy="0 ${pi/2} 0"/>
      <parent link="${prefix}flange"/>
      <child link="${prefix}tool0"/>
    </joint>

  </xacro:macro>
</robot>
